<sdf version='1.7'>
  <model name='arjuna_robot'>
    <link name='base_footprint'>
      <inertial>
        <pose>0.005202 0.000617 0.045561 0 -0 0</pose>
        <mass>5.27</mass>
        <inertia>
          <ixx>0.10289</ixx>
          <ixy>-0.000145593</ixy>
          <ixz>-0.00225699</ixz>
          <iyy>0.105411</iyy>
          <iyz>1.31973e-05</iyz>
          <izz>0.103347</izz>
        </inertia>
      </inertial>
      <collision name='base_footprint_fixed_joint_lump__base_link_collision'>
        <pose>0 0 0.0465 0 -0 0</pose>
        <geometry>
          <box>
            <size>0.29161 0.187 0.084</size>
          </box>
        </geometry>
        <surface>
          <contact>
            <ode/>
          </contact>
          <friction>
            <ode/>
          </friction>
        </surface>
      </collision>
      <collision name='base_footprint_fixed_joint_lump__camera_collision_1'>
        <pose>0.11 0 0.1815 0 -0 0</pose>
        <geometry>
          <box>
            <size>0.0175 0.091 0.028</size>
          </box>
        </geometry>
        <surface>
          <contact>
            <ode/>
          </contact>
          <friction>
            <ode/>
          </friction>
        </surface>
      </collision>
      <collision name='base_footprint_fixed_joint_lump__imu_collision_2'>
        <pose>0.05 0.065 0.0415 0 -0 0</pose>
        <geometry>
          <box>
            <size>0.027 0.02 0.004</size>
          </box>
        </geometry>
        <surface>
          <contact>
            <ode/>
          </contact>
          <friction>
            <ode/>
          </friction>
        </surface>
      </collision>
      <collision name='base_footprint_fixed_joint_lump__laser_collision_3'>
        <pose>0.11 0 0.1115 0 -0 3.14159</pose>
        <geometry>
          <box>
            <size>0.0556 0.0556 0.0413</size>
          </box>
        </geometry>
        <surface>
          <contact>
            <ode/>
          </contact>
          <friction>
            <ode/>
          </friction>
        </surface>
      </collision>
      <collision name='base_footprint_fixed_joint_lump__ultrasonic_left_collision_4'>
        <pose>0.1458 0.07 0.0615 0 -0 0</pose>
        <geometry>
          <cylinder>
            <length>0.02</length>
            <radius>0.01</radius>
          </cylinder>
        </geometry>
        <surface>
          <contact>
            <ode/>
          </contact>
          <friction>
            <ode/>
          </friction>
        </surface>
      </collision>
      <collision name='base_footprint_fixed_joint_lump__ultrasonic_right_collision_5'>
        <pose>0.1458 -0.07 0.0615 0 -0 0</pose>
        <geometry>
          <cylinder>
            <length>0.02</length>
            <radius>0.01</radius>
          </cylinder>
        </geometry>
        <surface>
          <contact>
            <ode/>
          </contact>
          <friction>
            <ode/>
          </friction>
        </surface>
      </collision>
      <visual name='base_footprint_fixed_joint_lump__base_link_visual'>
        <pose>0 0 0.0415 0 -0 0</pose>
        <geometry>
          <box>
            <size>0.29161 0.187 0.084</size>
          </box>
        </geometry>
        <material>
          <script>
            <name>Gazebo/Blue</name>
            <uri>file://media/materials/scripts/gazebo.material</uri>
          </script>
        </material>
      </visual>
      <visual name='base_footprint_fixed_joint_lump__camera_visual_1'>
        <pose>0.11 0 0.1815 0 -0 0</pose>
        <geometry>
          <box>
            <size>0.0175 0.091 0.028</size>
          </box>
        </geometry>
      </visual>
      <visual name='base_footprint_fixed_joint_lump__imu_visual_2'>
        <pose>0.05 0.065 0.0415 0 -0 0</pose>
        <geometry>
          <box>
            <size>0.027 0.02 0.004</size>
          </box>
        </geometry>
      </visual>
      <visual name='base_footprint_fixed_joint_lump__laser_visual_3'>
        <pose>0.11 0 0.1115 0 -0 3.14159</pose>
        <geometry>
          <cylinder>
            <length>0.0413</length>
            <radius>0.0278</radius>
          </cylinder>
        </geometry>
      </visual>
      <visual name='base_footprint_fixed_joint_lump__ultrasonic_left_visual_4'>
        <pose>0.1458 0.07 0.0615 0 -0 0</pose>
        <geometry>
          <cylinder>
            <length>0.02</length>
            <radius>0.01</radius>
          </cylinder>
        </geometry>
      </visual>
      <visual name='base_footprint_fixed_joint_lump__ultrasonic_right_visual_5'>
        <pose>0.1458 -0.07 0.0615 0 -0 0</pose>
        <geometry>
          <cylinder>
            <length>0.02</length>
            <radius>0.01</radius>
          </cylinder>
        </geometry>
      </visual>
      <sensor name='camera_sensor' type='camera'>
        <update_rate>30</update_rate>
        <camera name='head'>
          <horizontal_fov>1.39626</horizontal_fov>
          <image>
            <width>800</width>
            <height>800</height>
            <format>R8G8B8</format>
          </image>
          <clip>
            <near>0.02</near>
            <far>300</far>
          </clip>
          <noise>
            <type>gaussian</type>
            <mean>0</mean>
            <stddev>0.007</stddev>
          </noise>
        </camera>
        <plugin name='camera_controller' filename='libgazebo_ros_camera.so'>
          <ros>
            <namespace>arjuna</namespace>
            <remapping>image_raw:=camera/image_raw</remapping>
            <remapping>camera_info:=camera/camera_info</remapping>
          </ros>
          <camera_name>camera</camera_name>
          <frame_name>camera</frame_name>
          <hack_baseline>0.07</hack_baseline>
        </plugin>
        <pose>0.11 0 0.1815 0 -0 0</pose>
      </sensor>
      <gravity>1</gravity>
      <sensor name='imu_sensor' type='imu'>
        <always_on>1</always_on>
        <update_rate>100</update_rate>
        <visualize>1</visualize>
        <plugin name='imu_plugin' filename='libgazebo_ros_imu_sensor.so'>
          <ros>
            <namespace>/</namespace>
            <remapping>~/out:=imu/data</remapping>
          </ros>
          <frame_name>imu</frame_name>
          <initial_orientation_as_reference>0</initial_orientation_as_reference>
        </plugin>
        <pose>0.05 0.065 0.0415 0 -0 0</pose>
      </sensor>
      <sensor name='rplidar_c1' type='ray'>
        <visualize>0</visualize>
        <update_rate>10</update_rate>
        <ray>
          <scan>
            <horizontal>
              <samples>360</samples>
              <resolution>1</resolution>
              <min_angle>-3.14159</min_angle>
              <max_angle>3.14159</max_angle>
            </horizontal>
          </scan>
          <range>
            <min>0.05</min>
            <max>12</max>
            <resolution>0.01</resolution>
          </range>
          <noise>
            <type>gaussian</type>
            <mean>0</mean>
            <stddev>0.01</stddev>
          </noise>
        </ray>
        <plugin name='gazebo_ros_head_rplidar_controller' filename='libgazebo_ros_ray_sensor.so'>
          <ros>
            <remapping>~/out:=scan</remapping>
          </ros>
          <output_type>sensor_msgs/LaserScan</output_type>
          <frame_name>laser</frame_name>
        </plugin>
        <pose>0.11 0 0.1115 0 -0 3.14159</pose>
      </sensor>
      <sensor name='ultrasonic_sensor_left' type='ray'>
        <visualize>1</visualize>
        <update_rate>5</update_rate>
        <ray>
          <scan>
            <horizontal>
              <samples>5</samples>
              <resolution>1</resolution>
              <min_angle>-0.1</min_angle>
              <max_angle>0.1</max_angle>
            </horizontal>
            <vertical>
              <samples>5</samples>
              <resolution>1</resolution>
              <min_angle>-0.1</min_angle>
              <max_angle>0.1</max_angle>
            </vertical>
          </scan>
          <range>
            <min>0.02</min>
            <max>4</max>
            <resolution>0.01</resolution>
          </range>
        </ray>
        <plugin name='gazebo_ros_range_left' filename='libgazebo_ros_range.so'>
          <ros>
            <remapping>~/out:=/ultrasonic/left/range</remapping>
          </ros>
          <frame_name>ultrasonic_left</frame_name>
          <radiation_type>ultrasound</radiation_type>
          <fov>0.2</fov>
        </plugin>
        <pose>0.1458 0.07 0.0615 0 -0 0</pose>
      </sensor>
      <sensor name='ultrasonic_sensor_right' type='ray'>
        <visualize>1</visualize>
        <update_rate>5</update_rate>
        <ray>
          <scan>
            <horizontal>
              <samples>5</samples>
              <resolution>1</resolution>
              <min_angle>-0.1</min_angle>
              <max_angle>0.1</max_angle>
            </horizontal>
            <vertical>
              <samples>5</samples>
              <resolution>1</resolution>
              <min_angle>-0.1</min_angle>
              <max_angle>0.1</max_angle>
            </vertical>
          </scan>
          <range>
            <min>0.02</min>
            <max>4</max>
            <resolution>0.01</resolution>
          </range>
        </ray>
        <plugin name='gazebo_ros_range_right' filename='libgazebo_ros_range.so'>
          <ros>
            <remapping>~/out:=/ultrasonic/right/range</remapping>
          </ros>
          <frame_name>ultrasonic_right</frame_name>
          <radiation_type>ultrasound</radiation_type>
          <fov>0.2</fov>
        </plugin>
        <pose>0.1458 -0.07 0.0615 0 -0 0</pose>
      </sensor>
    </link>
    <joint name='front_wheel_left_joint' type='revolute'>
      <pose relative_to='base_footprint'>0.1458 0.1135 0.0415 -1.5707 0 0</pose>
      <parent>base_footprint</parent>
      <child>front_wheel_left</child>
      <axis>
        <xyz>0 0 1</xyz>
        <limit>
          <lower>-1e+16</lower>
          <upper>1e+16</upper>
        </limit>
        <dynamics>
          <spring_reference>0</spring_reference>
          <spring_stiffness>0</spring_stiffness>
        </dynamics>
      </axis>
    </joint>
    <link name='front_wheel_left'>
      <pose relative_to='front_wheel_left_joint'>0 0 0 0 -0 0</pose>
      <inertial>
        <pose>0 0 0 0 -0 0</pose>
        <mass>0.5</mass>
        <inertia>
          <ixx>0.001</ixx>
          <ixy>0</ixy>
          <ixz>0</ixz>
          <iyy>0.001</iyy>
          <iyz>0</iyz>
          <izz>0.001</izz>
        </inertia>
      </inertial>
      <collision name='front_wheel_left_collision'>
        <pose>0 0 0 0 -0 0</pose>
        <geometry>
          <cylinder>
            <length>0.04</length>
            <radius>0.0415</radius>
          </cylinder>
        </geometry>
        <surface>
          <contact>
            <ode>
              <kp>1e+06</kp>
              <kd>100</kd>
              <max_vel>0.1</max_vel>
              <min_depth>0.001</min_depth>
            </ode>
          </contact>
          <friction>
            <ode>
              <mu>1</mu>
              <mu2>1</mu2>
              <fdir1>1 0 0</fdir1>
            </ode>
          </friction>
        </surface>
      </collision>
      <visual name='front_wheel_left_visual'>
        <pose>0 0 0 0 -0 0</pose>
        <geometry>
          <cylinder>
            <length>0.04</length>
            <radius>0.0415</radius>
          </cylinder>
        </geometry>
        <material>
          <script>
            <name>Gazebo/FlatBlack</name>
            <uri>file://media/materials/scripts/gazebo.material</uri>
          </script>
        </material>
      </visual>
    </link>
    <joint name='front_wheel_right_joint' type='revolute'>
      <pose relative_to='base_footprint'>0.1458 -0.1135 0.0415 1.5707 -0 0</pose>
      <parent>base_footprint</parent>
      <child>front_wheel_right</child>
      <axis>
        <xyz>0 0 -1</xyz>
        <limit>
          <lower>-1e+16</lower>
          <upper>1e+16</upper>
        </limit>
        <dynamics>
          <spring_reference>0</spring_reference>
          <spring_stiffness>0</spring_stiffness>
        </dynamics>
      </axis>
    </joint>
    <link name='front_wheel_right'>
      <pose relative_to='front_wheel_right_joint'>0 0 0 0 -0 0</pose>
      <inertial>
        <pose>0 0 0 0 -0 0</pose>
        <mass>0.5</mass>
        <inertia>
          <ixx>0.001</ixx>
          <ixy>0</ixy>
          <ixz>0</ixz>
          <iyy>0.001</iyy>
          <iyz>0</iyz>
          <izz>0.001</izz>
        </inertia>
      </inertial>
      <collision name='front_wheel_right_collision'>
        <pose>0 0 0 0 -0 0</pose>
        <geometry>
          <cylinder>
            <length>0.04</length>
            <radius>0.0415</radius>
          </cylinder>
        </geometry>
        <surface>
          <contact>
            <ode>
              <kp>1e+06</kp>
              <kd>100</kd>
              <max_vel>0.1</max_vel>
              <min_depth>0.001</min_depth>
            </ode>
          </contact>
          <friction>
            <ode>
              <mu>1</mu>
              <mu2>1</mu2>
              <fdir1>1 0 0</fdir1>
            </ode>
          </friction>
        </surface>
      </collision>
      <visual name='front_wheel_right_visual'>
        <pose>0 0 0 0 -0 0</pose>
        <geometry>
          <cylinder>
            <length>0.04</length>
            <radius>0.0415</radius>
          </cylinder>
        </geometry>
        <material>
          <script>
            <name>Gazebo/FlatBlack</name>
            <uri>file://media/materials/scripts/gazebo.material</uri>
          </script>
        </material>
      </visual>
    </link>
    <joint name='rear_wheel_left_joint' type='revolute'>
      <pose relative_to='base_footprint'>-0.1458 0.1135 0.0415 -1.5707 0 0</pose>
      <parent>base_footprint</parent>
      <child>rear_wheel_left</child>
      <axis>
        <xyz>0 0 1</xyz>
        <limit>
          <lower>-1e+16</lower>
          <upper>1e+16</upper>
        </limit>
        <dynamics>
          <spring_reference>0</spring_reference>
          <spring_stiffness>0</spring_stiffness>
        </dynamics>
      </axis>
    </joint>
    <link name='rear_wheel_left'>
      <pose relative_to='rear_wheel_left_joint'>0 0 0 0 -0 0</pose>
      <inertial>
        <pose>0 0 0 0 -0 0</pose>
        <mass>0.5</mass>
        <inertia>
          <ixx>0.001</ixx>
          <ixy>0</ixy>
          <ixz>0</ixz>
          <iyy>0.001</iyy>
          <iyz>0</iyz>
          <izz>0.001</izz>
        </inertia>
      </inertial>
      <collision name='rear_wheel_left_collision'>
        <pose>0 0 0 0 -0 0</pose>
        <geometry>
          <cylinder>
            <length>0.04</length>
            <radius>0.0415</radius>
          </cylinder>
        </geometry>
        <surface>
          <contact>
            <ode>
              <kp>1e+06</kp>
              <kd>100</kd>
              <max_vel>0.1</max_vel>
              <min_depth>0.001</min_depth>
            </ode>
          </contact>
          <friction>
            <ode>
              <mu>1</mu>
              <mu2>1</mu2>
              <fdir1>1 0 0</fdir1>
            </ode>
          </friction>
        </surface>
      </collision>
      <visual name='rear_wheel_left_visual'>
        <pose>0 0 0 0 -0 0</pose>
        <geometry>
          <cylinder>
            <length>0.04</length>
            <radius>0.0415</radius>
          </cylinder>
        </geometry>
        <material>
          <script>
            <name>Gazebo/FlatBlack</name>
            <uri>file://media/materials/scripts/gazebo.material</uri>
          </script>
        </material>
      </visual>
    </link>
    <joint name='rear_wheel_right_joint' type='revolute'>
      <pose relative_to='base_footprint'>-0.1458 -0.1135 0.0415 1.5707 -0 0</pose>
      <parent>base_footprint</parent>
      <child>rear_wheel_right</child>
      <axis>
        <xyz>0 0 -1</xyz>
        <limit>
          <lower>-1e+16</lower>
          <upper>1e+16</upper>
        </limit>
        <dynamics>
          <spring_reference>0</spring_reference>
          <spring_stiffness>0</spring_stiffness>
        </dynamics>
      </axis>
    </joint>
    <link name='rear_wheel_right'>
      <pose relative_to='rear_wheel_right_joint'>0 0 0 0 -0 0</pose>
      <inertial>
        <pose>0 0 0 0 -0 0</pose>
        <mass>0.5</mass>
        <inertia>
          <ixx>0.001</ixx>
          <ixy>0</ixy>
          <ixz>0</ixz>
          <iyy>0.001</iyy>
          <iyz>0</iyz>
          <izz>0.001</izz>
        </inertia>
      </inertial>
      <collision name='rear_wheel_right_collision'>
        <pose>0 0 0 0 -0 0</pose>
        <geometry>
          <cylinder>
            <length>0.04</length>
            <radius>0.0415</radius>
          </cylinder>
        </geometry>
        <surface>
          <contact>
            <ode>
              <kp>1e+06</kp>
              <kd>100</kd>
              <max_vel>0.1</max_vel>
              <min_depth>0.001</min_depth>
            </ode>
          </contact>
          <friction>
            <ode>
              <mu>1</mu>
              <mu2>1</mu2>
              <fdir1>1 0 0</fdir1>
            </ode>
          </friction>
        </surface>
      </collision>
      <visual name='rear_wheel_right_visual'>
        <pose>0 0 0 0 -0 0</pose>
        <geometry>
          <cylinder>
            <length>0.04</length>
            <radius>0.0415</radius>
          </cylinder>
        </geometry>
        <material>
          <script>
            <name>Gazebo/FlatBlack</name>
            <uri>file://media/materials/scripts/gazebo.material</uri>
          </script>
        </material>
      </visual>
    </link>
    <static>0</static>
    <plugin name='diff_drive' filename='libgazebo_ros_diff_drive.so'>
      <num_wheel_pairs>2</num_wheel_pairs>
      <left_joint>front_wheel_left_joint</left_joint>
      <left_joint>rear_wheel_left_joint</left_joint>
      <right_joint>front_wheel_right_joint</right_joint>
      <right_joint>rear_wheel_right_joint</right_joint>
      <wheel_separation>0.227</wheel_separation>
      <wheel_diameter>0.083</wheel_diameter>
      <max_wheel_torque>20</max_wheel_torque>
      <max_wheel_acceleration>1.0</max_wheel_acceleration>
      <publish_odom>1</publish_odom>
      <publish_odom_tf>1</publish_odom_tf>
      <publish_wheel_tf>0</publish_wheel_tf>
      <publish_wheel_joint_state>1</publish_wheel_joint_state>
      <publishWheelTF>0</publishWheelTF>
      <publishWheelJointState>1</publishWheelJointState>
      <odometry_frame>odom</odometry_frame>
      <robot_base_frame>base_footprint</robot_base_frame>
    </plugin>
    <plugin name='joint_state_publisher' filename='libgazebo_ros_joint_state_publisher.so'>
      <update_rate>30</update_rate>
      <joint_name>front_wheel_left_joint</joint_name>
      <joint_name>front_wheel_right_joint</joint_name>
      <joint_name>rear_wheel_left_joint</joint_name>
      <joint_name>rear_wheel_right_joint</joint_name>
    </plugin>
  </model>
</sdf>
